Workbook

Sheet Estimate
A1: අ.අ. | B1: විස්තරය | D1: අනුමත දීමනාව රුපියල් | E1: දින ගණන /පැය ගණන | F1: පුද්ගල සංඛ්‍යාව | G1: ඇස්තමේන්තු වියදම රුපියල් | H1: වියදම් එකතුව
A2: 1 | B2: සහභාගිත්ව දීමනා | H2: 0
B3: i | C3: පරිවේණාධිපති/පරිවේණාචාර්ය - නේවාසික | D3: 500 | E3: 0 | F3: 0 | G3: 0
B4: ii | C4: පරිවේණාධිපති/පරිවේණාචාර්ය - නේවාසික නොවන | D4: 400 | E4: 0 | F4: 0 | G4: 0
A5: 2 | B5: සංවිධාන හා මෙහෙයවීම - වැඩමුළු දිනක් සඳහා (එක් අයකුට පමණි) | D5: 500 | E5: 0 | F5: 0 | G5: 0 | H5: 0
A6: 3 | B6: අධීක්ෂණ - වැඩමුළු දිනක් සඳහා (එක් අයෙකුට පමණි) | D6: 600 | E6: 0 | F6: 0 | G6: 0 | H6: 0
A7: 4 | B7: මධ්‍යස්ථාන / ශාලා ගාස්තු | D7: 45000 | E7: 0 | F7: - | G7: 0 | H7: 0
A8: 5 | B8: මූල්‍ය අධීක්ෂණය (එක් වැඩසටහනකට, එක් නිලධාරියෙකුට එක් දිනක් සඳහා පමණි) | H8: 0
B9: i | C9: ගණකාධිකාරී | D9: 600 | E9: 0 | F9: 0 | G9: 0
A10: 6 | B10: සහාය කාර්යමණ්ඩල සඳහා | H10: 0
B11: i | C11: මධ්‍යස්ථාන / නේවාසිකාගාර භාරකරු (එක් දිනකට පමණි) | D11: 350 | E11: 0 | F11: 0 | G11: 0
B12: ii | C12: සරප් (එක් දිනකට පමණි) | D12: 350 | E12: 0 | F12: 0 | G12: 0
B13: iii | C13: කළමනාකරණ සේවා / සංවර්ධන නිලධාරී - ආයතන (එක් වැඩසටහනකට එක් අයෙකුට පමණක්) | D13: 3250 | E13: 0 | F13: 0 | G13: 0
B14: iv | C14: රියැදුරු | D14: 3000 | E14: 0 | F14: 0 | G14: 0
B15: v | C15: කා.කා.ස./කම්කරු/විද්‍යාගාර සහායක/පුස්තකාල සහායක | D15: 2700 | E15: 0 | F15: 0 | G15: 0
A16: 7 | B16: සම්පත්දායක දීමනා (දිනකට පැය 03 ක උපරිමයට යටත් ව / විශ්‍රාමික නිලධරයන් සඳහා දිනකට උපරිම පැය 06) | H16: 0
B17: i | C17: පිළිගත් විශ්ව විද්‍යාලයක ජ්‍යෙෂ්ඨ මහාචාර්යවරුන්/ මහාචාර්යවරුන් (සේවා නියුක්ත හා විශ්‍රාමික) | D17: 2400 | E17: 0 | F17: 0 | G17: 0
C18: ශ්‍රී ලං:ප:සේ: හා සමාන්තර දීප ව්‍යාප්ත සේවාවල විශේෂ ශ්‍රේණියේ නිලධාරීන් (සේවා නියුක්ත හා විශ්‍රාමික) | D18: 2400 | E18: 0 | F18: 0 | G18: 0
C19: රාජ්‍ය සංස්ථා හෝ ව්‍යවස්ථාපිත මණ්ඩලවල ජ්‍යෙෂ්ඨ කළමනාකාර මට්ටමේ C 2-1, C 2-2 හා C 2-3 සේවා ගණවල නිලධාරීන් | D19: 2400 | E19: 0 | F19: 0 | G19: 0
B20: ii | C20: පිළිගත් විශ්ව විද්‍යාලයක ජ්‍යෙෂ්ඨ කථිකාචාර්යවරුන් (සේවා නියුක්ත හා විශ්‍රාමික) | D20: 2000 | E20: 0 | F20: 0 | G20: 0
C21: ශ්‍රී ලං:ප:සේ: හා සමාන්තර දීප ව්‍යාප්ත සේවාවල I වන පන්තියේ නිලධාරීන් (සේවා නියුක්ත හා විශ්‍රාමික) | D21: 2000 | E21: 0 | F21: 0 | G21: 0
C22: ගුරු අධ්‍යාපනඥ සේවයේ I වන පන්තියේ නිලධාරීන් (සේවා නියුක්ත හා විශ්‍රාමික) | D22: 2000 | E22: 0 | F22: 0 | G22: 0
C23: රාජ්‍ය සංස්ථා හෝ ව්‍යවස්ථාපිත මණ්ඩලවල ජ්‍යෙෂ්ඨ කළමනාකාර මට්ටමේ C 1-1, C 1-2 හා C 1-3, AR 2 සේවා ගණවල නිලධාරීන් | D23: 2000 | E23: 0 | F23: 0 | G23: 0
B24: iii | C24: පිළිගත් විශ්ව විද්‍යාලයක කථිකාචාර්යවරුන් | D24: 1800 | E24: 0 | F24: 0 | G24: 0
C25: ශ්‍රී ලං:ප:සේ: හා සමාන්තර දීප ව්‍යාප්ත සේවාවල II වන පන්තියේ නිලධාරීන් | D25: 1800 | E25: 0 | F25: 0 | G25: 0
C26: ගුරු අධ්‍යාපනඥ සේවයේ II වන පන්තියේ නිලධාරීන් | D26: 1800 | E26: 0 | F26: 0 | G26: 0
C27: රාජ්‍ය සංස්ථා හෝ ව්‍යවස්ථාපිත මණ්ඩලවල මධ්‍යම කළමනාකාර මට්ටමේ C 2 හා C 3 සේවා ගණවල නිලධාරීන් හා ජ්‍යෙෂ්ඨ අධ්‍යයන/පර්යේෂණ සේවා ගණයේ AR-2 ඛණ්ඩයේ වැටුප් ලබන්නන් | D27: 1800 | E27: 0 | F27: 0 | G27: 0
B28: iv | C28: පිළිගත් විශ්ව විද්‍යාලයක ආධුනික කථිකාචාර්යවරුන් | D28: 1600 | E28: 0 | F28: 0 | G28: 0
C29: ශ්‍රී ලං:ප:සේ: හා සමාන්තර දීප ව්‍යාප්ත සේවාවල III වන පන්තියේ නිලධාරීන් | D29: 1600 | E29: 0 | F29: 0 | G29: 0
C30: ගුරු අධ්‍යාපනඥ සේවයේ III වන පන්තියේ නිලධාරීන් | D30: 1600 | E30: 0 | F30: 0 | G30: 0
C31: රාජ්‍ය සංස්ථා හෝ ව්‍යවස්ථාපිත මණ්ඩලවල මධ්‍යම කළමනාකාර මට්ටමේ C 1 හා අධ්‍යයන/පර්යේෂණ සේවා ගණයේ AR-1 ඛණ්ඩයේ වැටුප් ලබන්නන් | D31: 1600 | E31: 0 | F31: 0 | G31: 0
C32: පිළිගත් විශ්ව විද්‍යාලයක පශ්චාත් උපාධි ඩිප්ලෝමාධාරීන් (පෞද්ගලික අංශයේ සේවයේ නියුතු) | D32: 1600 | E32: 0 | F32: 0 | G32: 0
B33: v | C33: ශ්‍රී ලංකා විදුහල්පති සේවයේ නිලධාරීන් / පරිවේණාධිපති හිමිවරුන් | D33: 1400 | E33: 0 | F33: 0 | G33: 0
C34: ශ්‍රී ලංකා ගුරු / පරිවේණාචාර්ය සේවයේ 1 පන්තියේ නිලධාරීන් | D34: 1400 | E34: 0 | F34: 0 | G34: 0
C35: ගුරු උපදේශකවරුන් | D35: 1400 | E35: 0 | F35: 0 | G35: 0
C36: පිළිගත් විශ්ව විද්‍යාලයක උපාධිධාරීන් | D36: 1400 | E36: 0 | F36: 0 | G36: 0
C37: කනිෂ්ඨ කළමනාකරණ සේවා ගණයේ නිලධාරීන් | D37: 1400 | E37: 0 | F37: 0 | G37: 0
B38: vi | C38: අනෙකුත් සුදුසුකම් සහිත නිලධාරීන් | D38: 1200 | E38: 0 | F38: 0 | G38: 0
A39: 8 | B39: ආහාරපාන හා සංග්‍රහ වියදම් | H39: 0
B40: i | C40: උදෑසන තේ - නේවාසික වැඩසටහන් සඳහා පමණි. | D40: 100 | E40: 0 | F40: 0 | G40: 0
...

Sheet Data_Log
A1: දිනය | B1: පරිශීලක | C1: වැය ශීර්ෂය | D1: Action No | E1: වැඩසටහන | F1: ස්ථානය | G1: දිනය | H1: ප්‍රතිලාභීන් | I1: ඇස්තමේන්තුව | J1: වියදම
A2: 46156.592 | B2: sub_tripitaka | C2: 126-2-05-002-2205 | D2: 16.7.4 | E2: ත්‍රිපිටක ධර්මය විෂය පුහුණු සැලැස්ම | F2: විභාග දෙපාර්තමේන්තුව | G2: 46072 | H2: 28 | I2: 215350 | J2: 188350
A3: 46156.594 | B3: sub_tripitaka | C3: 126-2-05-002-2205 | D3: 16.7.4 | E3: ත්‍රිපිටක ධර්මවිෂය නිපුණතා පරික්ෂණ පිළිබ ද මාණ්ඩලික නිලධාරි දැනුවත් කිරීම | F3: අධ්‍යාපන අමාත්‍යාංශය | G3: 46119 | H3: 40 | I3: 15300 | J3: 13000
A4: 46156.611 | B4: sub_seethawala | C4: 126-2-05-002-2205 | D4: 16.7.30 | E4: දසදින නේවාසික පුහුණුව | F4: සීතාවකපුර පිරිවෙන් ගුරු අභ්‍යාස ආයතනය | G4: 46133 | H4: 30 | I4: 579315 | J4: 552355
A5: 46162.416 | B5: off_ep | C5: 126-2-05-002-2205 | D5: 16.7.25 | E5: කෘත්‍යාධිකාරී පරිවෙණාධිපති කළමනාකරණ පුහුණු වැඩමුළුව. | F5: පළාත් අධ්‍යාපන දෙපාර්තමේන්තුව නැගෙනහිර. | G5: 46149 | H5: 30 | I5: 69180 | J5: 59670
A6: 46167.456 | B6: sub_tripitaka | C6: 126-2-05-002-2205 | D6: 16.7.18 | E6: සති සක්‍යතා හා ආකල්ප සංවර්ධන නායකත්ව පුහුණු පස්දින වැඩ සටහන | F6: මිතිරිගල , නිස්සරණ වන සෙනසුන | G6: 46052 | H6: 70 | I6: 399000 | J6: 96300
A7: 46168.344 | B7: sub_tripitaka | C7: 126-2-05-002-2205 | D7: 16.7.2 | E7: පාලි විෂය ඉගෙනුම්, ඉගැන්විම, ධාරිතා සංවර්ධන හා ප්‍රතිපල ඉහළ නැංවිමේ නේවාසික වැඩමුළුව | F7: ප්‍රජා අධ්‍යාපන මධ්‍යස්ථානය - තලාහේන - මාලඹේ | G7: 46162 | H7: 45 | I7: 564825 | J7: 401552
A8: 46169.647 | B8: sub_seethawala | C8: 126-2-05-002-2205 | D8: 16.7.30 | E8: නවක පරිවේණාචාර්යවරුන් සඳහා වු දසදින නේවාසික පුහුණු වැඩසටහන ( 10 වන කණ්ඩායම) | F8: සීතාවකපුර පිරිවෙන් ගුරු අභ්‍යාස ආයතනය | G8: 46080 | H8: 31 | I8: 263302.5 | J8: 243050.5
A9: 46169.655 | B9: sub_seethawala | C9: 126-2-05-002-2205 | D9: 16.7.30 | E9: නවක පරිවේණාචාර්යවරුන් සඳහා වු දසදින නේවාසික පුහුණු වැඩසටහන ( 09 වන කණ්ඩායම) | F9: සීතාවකපුර පිරිවෙන් ගුරු අභ්‍යාස ආයතනය | G9: 46066 | H9: 29 | I9: 267187.5 | J9: 304159.5
A10: 46169.66 | B10: sub_seethawala | C10: 126-2-05-002-2205 | D10: 16.7.30 | E10: නවක පරිවේණාචාර්යවරුන් සඳහා වු දසදින නේවාසික පුහුණු වැඩසටහන ( 11 වන කණ්ඩායම) | F10: සිතාවකපුර පිරිවෙන් ගුරු අභ්‍යාස ආයතනය | G10: 46101 | H10: 31 | I10: 306127.5 | J10: 327401.5 | K10: =SUM(J2,J2:J10) -> 2374188.5
A11: 46206.446 | B11: sub_tripitaka | C11: 126-2-05-002-2205 | D11: 16.7.2 | E11: ගුරු උපදේශක හා ප්‍රවිණ පරිවේණාචාර්යවරුන්ගේ තෙදින නේවාසික වැඩ සටහන (TOT) 2026.06.24.25.26 | F11: ප්‍රජා අධ්‍යාපන මධ්‍යස්ථානය, තලහේන, මාලඹේ | G11: 46197 | H11: 49 | I11: 701550 | J11: 610288
A12: 46212.367 | B12: sub_tripitaka | C12: 126-2-05-002-2205 | D12: 16.7.2 | E12: 201.202.203.මණ්ඩලයේ අනුමත නවක පරිවේණාචාර්යවරුන්ගේ ධාරිතා සංවර්ධන තෙදින වැඩ සටහන | F12: ප්‍රජා අධ්‍යාපන මධ්‍යස්ථානය, තලහේන, මාලඹේ | G12: 46180 | H12: 50 | I12: 661650 | J12: 435572
A13: 46212.376 | B13: sub_tripitaka | C13: 126-2-05-002-2205 | D13: 16.7.18 | E13: සති ශක්‍යතා හා අකාල්ප සංවර්ධන නායකත්ව පුහුණ පස්දින වැඩ සටහන ඉංග්‍රිසි පිරිවෙන්හි විෂය උගන්වන තොරාගත් පරිවේණාචාර්ය වරුන් සදහා | F13: මිතිරිගල නිස්සරණ වන සෙනසුන | G13: 46195 | H13: 80 | I13: 439400 | J13: 206109
A14: 46220.652 | B14: sub_seethawala | C14: 126-2-05-002-2205 | D14: 16.7.30 | E14: නවක පරිවේණාචාර්යවරුන් සඳහා වු දසදින නේවාසික පුහුණු වැඩසටහන (13 කණ්ඩායම) | F14: සීතාවකපුර පිරිවෙන් ගුරු අභ්‍යාස ආයතනය | G14: 46164 | H14: 32 | I14: 578835 | J14: 530585
A15: 46222.678 | B15: dep_ncp | C15: 126-2-05-002-2205 | D15: 16.7.26 | E15: ධාරිතා සංවර්ධන වැඩසටහන (පරිවේණාධිපති) | F15: අධ්‍යාපන සංවර්ධන මධ්‍යස්ථානය, අනුරාධපුර | G15: 46163 | H15: 60 | I15: 95600 | J15: 85400
A16: 46222.705 | B16: super_admin | C16: 126-2-05-002-2205 | D16: 16.9.4 | E16: සිසු නිපණතා ඇගයීම | F16: ශ්‍රී ගුණරතන පිරිවෙන | G16: 46241 | H16: 353 | I16: 99950 | J16: 99950
A17: 46223.405 | B17: sub_sinhala | C17: 126-2-05-002-2205 | D17: 16.7.1 | E17: සිංහල විෂය ගුරු උපදේශක හා ජ්‍යේෂ්ඨ ගුරුවරුන් ධාරිතා සංවර්ධන වැඩසටහන තෙදින | F17: ති රතන ආයතනය -කොට්ටාව | G17: 46029 | H17: 38 | I17: 322950 | J17: 235295
A18: 46223.416 | B18: off_up | C18: 126-2-05-002-2205 | D18: 16.7.28 | E18: සිංහල විෂය ගුරු ධාරිතා පුහුණු වැඩසටහන | F18: සම්පත් මධ්‍යස්ථානය - හාලිඇල | G18: 46196 | H18: 45 | I18: 58300 | J18: 58300
A19: 46223.421 | B19: off_up | C19: 126-2-05-002-2205 | D19: 16.7.28 | E19: සෞඛ්‍ය විද්‍යාව විෂය ගුරු ධාරිතා පුහුණු වැඩසටහන | F19: සම්පත් මධ්‍යස්ථානය - හාලිඇල | G19: 46197 | H19: 42 | I19: 58300 | J19: 58300
A20: 46223.424 | B20: off_up | C20: 126-2-05-002-2205 | D20: 16.7.28 | E20: ත්‍රිපිටක ධර්මය ගුරු ධාරිතා පුහුණු වැඩසටහන | F20: සම්පත් මධ්‍යස්ථානය -හාලිඇල | G20: 46198 | H20: 42 | I20: 58300 | J20: 58300
A21: 46223.427 | B21: sub_english | C21: 126-2-05-002-2205 | D21: 16.7.6 | E21: ඉංග්‍රීසි ගුරු උපදේශකවරුන හා ජ්‍යෙෂ්ඨ පරිටෙව්ණාචාර්යවරුන් පුහුණු කිරීමේ වැඩසටහන | F21: හාරගම සම්පත් මධ්‍යස්ථානය | G21: 46181 | H21: 38 | I21: 484160 | J21: 398014
A22: 46223.427 | B22: off_up | C22: 126-2-05-002-2205 | D22: 16.7.28 | E22: ඉංග්‍රිසි විෂය ගුරු ධාරිතා පුහුණු වැඩසටහන | F22: සම්පත් මධ්‍යස්ථානය - හාලිඇල | G22: 46199 | H22: 42 | I22: 58300 | J22: 58300
... A56: 46254.438 | B56: off_wp | C56: 126-2-05-002-2205 | D56: 16.7.22 | E56: කෘත්‍යාධිකාරි / පරිවෙණාධිපති කලමනාකරණ ධාරිතා සංවර්ධන වැඩමුළුව | F56: ගම්/විද්‍යාවංශ මහ පිරිවෙන, බණ්ඩාරවත්ත | G56: 46245 | H56: 150 | I56: 201495.88 | J56: 178895.88

Sheet Voucher_Log
A1: දිනය | B1: පරිශීලක | C1: වැය ශීර්ෂය | D1: Action No | E1: විස්තරය | F1: වවුචර අංකය | G1: වවුචර දිනය | H1: මුදල
A2: 46156.517 | B2: dev_do1 | C2: 126-2-05-002-1202(009) | D2: 5.0 | E2: ප්‍රත්‍යාවලෝකන පිරිවෙන් අධීක්ෂණය - බදුල්ල දිස්ත්‍රික්කය 2026.05.05-2026.05.09 දින දක්වා | F2: 1 | G2: 46153 | H2: 34104
A3: 46169.394 | B3: dev_do1 | C3: 126-2-05-002-1202(009) | D3: 5.0 | E3: හම්බන්තොට දිස්ත්‍රික් පිරිවෙන් අධීක්ෂණය - 2026.05.19 - 2026.05.21 | F3: 46055 | G3: 46164 | H3: 13328
A4: 46169.426 | B4: dev_do1 | C4: 126-2-05-002-1202(009) | D4: 5.0 | E4: පිරිවෙන් අධීක්ෂණය - මහනුවර, මාතලේ සහ නුවරඑළිය දිස්ත්‍රික්ක - 2026.05.18 - 2026.05.21 | F4: 3 | G4: 46168 | H4: 19600
A5: 46198.454 | B5: dev_do1 | C5: 126-2-05-002-1202(009) | D5: 5.0 | E5: අනුරාධපුර, පොළොන්නරුව, ත්‍රීකුණාමලය හා කුරුණෑගල දිස්ත්‍රික් පිරිවෙන් අධීක්ෂණයට යාම හා ඒම වෙනුවෙන් ඉන්ධන වියදම -2026.06.01-206.06.04 දක්වා | F5: 4 | G5: 46181 | H5: 33781
A6: 46198.642 | B6: dev_do1 | C6: 126-2-05-002-1202(009) | D6: 5.0 | E6: ගාල්ල හා මාතර දිස්ත්‍රික්කවල පිරිවෙන් අධීක්ෂණය වෙනුවෙන් ඉන්ධන වියදම - 2026.06.09 හා10 | F6: 5 | G6: 46188 | H6: 40293
A7: 46222.651 | B7: super_admin | C7: 126-2-05-002-1508 | D7: 10.0 | E7: වාර්ෂික ආධාර මුදල් ගෙවීම | F7: 2026 | G7: 46029 | H7: 151476078
B8: super_admin | C8: 126-2-05-010-1501 | D8: 11.0 | E8: පිරිවෙන් සිසුන් සඳහා පාවහන් තිළිනපත් ලබා ගැනීමට මුදල් පවරා ඇත | F8: 1 | H8: 40822500
A9: 46223.527 | B9: super_admin | C9: 126-2-05-002-1001 | D9: 1.0 | E9: ජුනි 30 දිනට වැටුප් | F9: 1 | G9: 46223 | H9: 3.6301741e+09
A10: 46223.528 | B10: super_admin | C10: 126-2-05-002-1003 | D10: 2.0 | E10: ජුලි 30 දිනට | F10: 2 | G10: 46223 | H10: 9.0849167e+08
A11: 46223.529 | B11: super_admin | C11: 126-2-05-002-1101 | D11: 3.0 | E11: ජුනි 30 ට ගමන් වියදම් | F11: 3 | G11: 46223 | H11: 12817458
A12: 46223.529 | B12: super_admin | C12: 126-2-05-002-1201 | D12: 4.1 | E12: ජුනි 30 දිනට | F12: 4 | G12: 46223 | H12: 1875839
A13: 46223.53 | B13: super_admin | C13: 126-2-05-002-1202(009) | D13: 5.0 | E13: ජුනි 30 ට | F13: 5 | G13: 46223 | H13: 475042
A14: 46223.531 | B14: super_admin | C14: 126-2-05-002-1409(140) | D14: 8.9 | E14: අගෝස්තු 31 ට | F14: 6 | G14: 46223 | H14: 3989013.1
A15: 46223.57 | B15: super_admin | C15: 126-2-05-002-1506 | D15: 9.0 | E15: අගෝස්තු 31 ට | F15: 8 | G15: 46223 | H15: 2948956.6

Sheet 12
A1: action No | B1: Activity (C) | C1: Vote Number | D1: Allocation | E1: Parent_No
A2: 1 | B2: Salaries and Wages | C2: 126-2-05-002-1001 | D2: 6000000 | E2: 1
A3: 2 | B3: Other Allowances | C3: 126-2-05-002-1003 | D3: 1600000 | E3: 2
A4: 3 | B4: Domestic | C4: 126-2-05-002-1101 | D4: 20000 | E4: 3
A5: 4 | B5: Stationary and office Requisites (Providing stationery to 825 Pirivena institutions) | C5: 126-2-05-002-1201
A6: 4.1 | B6: Stationary and office Requisites (Providing stationery to 485 Pirivena institutions) | C6: 126-2-05-002-1201 | D6: 7500 | E6: 4.1
A7: 4.2 | B7: Providing Book sets for llibraries of 825 Pirivenas. | C7: 126-2-05-002-1201 | D7: 7500 | E7: 4.2
A8: 5 | B8: Fuel - To implement the PEQI quality indicators of Pirivena institutions and Other Programmes | C8: 126-2-05-002-1202(009) | D8: 12000 | E8: 5
A9: 6 | B9: Postal and Communication | C9: 126-2-05-002-1402 | D9: 1000 | E9: 6
A10: 7 | B10: Electricity and Water | C10: 126-2-05-002-1403 | D10: 16750 | E10: 7
A11: 8 | B11: Other- Miscellaneous Service Expenditure | C11: 126-2-05-002-1409(140)
A12: 8.1 | B12: District and All-Ceylon Inter-Piriven Language and Literature Competitions | C12: 126-2-05-002-1409(140) | D12: 3000 | E12: 8.1
A13: 8.2 | B13: Printing of Teacher Performance Index and Professional Guidances | C13: 126-2-05-002-1409(140) | D13: 3000 | E13: 8.2
A14: 8.3 | B14: Printing of Class Management Performance Index and Guidances | C14: 126-2-05-002-1409(140) | D14: 3000 | E14: 8.3
A15: 8.4 | B15: Preparation and printing expenses for question papers for end-of-term examinations | C15: 126-2-05-002-1409(140) | D15: 7000 | E15: 8.4
A16: 8.5 | B16: Succession allowances for Pirivena teachers undergoing training at the Seethawaka Teacher Training Institute | C16: 126-2-05-002-1409(140) | D16: 2000 | E16: 8.5
A17: 8.6 | B17: Administrative expenses for holding the Pirivena Education Board | C17: 126-2-05-002-1409(140) | D17: 1500 | E17: 8.6
A18: 8.7 | B18: Providing allowances for extra resource persons assigned to teach Tamil in Pirivenas | C18: 126-2-05-002-1409(140) | D18: 2160 | E18: 8.7
A19: 8.8 | B19: Launching and printing of the "Saragaveshi" Action Research Journal. | C19: 126-2-05-002-1409(140) | D19: 1500 | E19: 8.8
A20: 8.9 | B20: Special extra curricular activities and national talent evaluation program to be held on the occasion of National Pirivena Day | C20: 126-2-05-002-1409(140) | D20: 1500 | E20: 8.9
A21: 8.1 | B21: Participation allowances for monitoring the standards of the Pirivena Education Quality index (PEQI) | C21: 126-2-05-002-1409(140) | D21: 1500 | E21: 8.1
A22: 8.11 | B22: Teacher Training Pay Back (Ed. Dip & Training Programmes) | C22: 126-2-05-002-1409(140) | D22: 1000 | E22: 8.11
A23: 8.12 | B23: Program for evaluating teachers who have demonstrated national talent on the occasion of World Teachers' Day | C23: 126-2-05-002-1409(140) | D23: 2840 | E23: 8.12
... A27: 12 | B27: Covering the annual estimated cost for the repair and maintenance of office equipment and electronic devices used in the Pirivena Education Division. | C27: 126-1-02-000-2002 | D27: 8000 | E27: 12
A28: 13 | B28: Rehabilitation and Improvement of Capital Assets | C28: 126-1-02-000-2003
A29: 13.1 | B29: Vehicles | C29: 126-1-02-000-2003 | D29: 10000 | E29: 13.1
A30: 14 | B30: Acquisition of essential office equipment and furniture for the Pirivena Education Division. | C30: 126-1-02-000-2102
A31: 14.1 | B31: No. of 5 Office Steel Cabinet (Small) | C31: 126-1-02-000-2102 | D31: 262 | E31: 14.1
A32: 14.2 | B32: Purchase No. of 3 new desktop computers. | C32: 126-1-02-000-2102 | D32: 937 | E32: 14.2
A33: 15 | B33: Staff Officer Training | C33: 126-1-02-000-2401
A34: 15.1 | B34: Staff Level Officer Training | C34: 126-1-02-000-2401 | D34: 400 | E34: 15.1
A35: 15.2 | B35: External training programs for tertiary staff belonging to the integrated services | C35: 126-1-02-000-2401 | D35: 400 | E35: 15.2
A36: 15.3 | B36: Training programs for junior employees | C36: 126-1-02-000-2401 | D36: 200 | E36: 15.3
A37: 16 | B37: Capital Grant to Non-Public Institution | C37: 126-2-05-002-2205
A38: 16.1 | B38: Renovation of buildings and development of infrastructure facilities in identified Pirivenas | C38: 126-2-05-002-2205 | D38: 78250 | E38: 16.1
A39: 16.2 | B39: Development of 22 model Pirivenas, one per district out of the 825 currently registered Pirivenas (Rs. 5 million * 22) | C39: 126-2-05-002-2205 | D39: 110000 | E39: 16.2
A40: 16.3 | B40: Development of infrastructure facilities at Seethavakapura Piriven Teacher Traning Institute and Veneamulla Teacher Institute. | C40: 126-2-05-002-2205 | D40: 3000 | E40: 16.3
A41: 16.4 | B41: Providing a grant of Rs. 75,000/= each for the maintenance of aesthetic equipments in 65 Vidyayatana Pirivenas. | C41: 126-2-05-002-2205 | D41: 4875 | E41: 16.4
A42: 16.5 | B42: Providing equipments and chemicals for Pirivena science laboratories | C42: 126-2-05-002-2205 | D42: 4500 | E42: 16.5
A43: 16.6 | B43: Providing equipment for practical tests in subjects such as Technology and Geography | C43: 126-2-05-002-2205 | D43: 2000 | E43: 16.6
...

Sheet AIP_Reference
A1: Parent No | B1: Vote Code | C1: Activity Name | D1: Category | E1: Allocation (Rs. '000)
A2: 1.0 | B2: 126-2-05-002-1001 | C2: Salaries and Wages | D2: Recurrent | E2: 6000000 | F2: =SUMIF(Data_Log!D:D, A2, Data_Log!J:J) -> 0
A3: 2.0 | B3: 126-2-05-002-1003 | C3: Other Allowances | D3: Recurrent | E3: 1600000 | F3: =SUMIF(Data_Log!D:D, A3, Data_Log!J:J) -> 0
A4: 3.0 | B4: 126-2-05-002-1101 | C4: Domestic | D4: Recurrent | E4: 20000 | F4: =SUMIF(Data_Log!D:D, A4, Data_Log!J:J) -> 0
A5: 4.0 | B5: 126-2-05-002-1201 | C5: Stationary and office Requisites (Providing stationery to 825 Pirivena institutions) | D5: Recurrent | F5: =SUMIF(Data_Log!D:D, A5, Data_Log!J:J) -> 0
A6: 4.1 | B6: 126-2-05-002-1201 | C6: Stationary and office Requisites (Providing stationery to 485 Pirivena institutions) | D6: Recurrent | E6: 7500 | F6: =SUMIF(Data_Log!D:D, A6, Data_Log!J:J) -> 0
A7: 4.2 | B7: 126-2-05-002-1201 | C7: Providing Book sets for llibraries of 825 Pirivenas. | D7: Recurrent | E7: 7500 | F7: =SUMIF(Data_Log!D:D, A7, Data_Log!J:J) -> 0
A8: 5.0 | B8: 126-2-05-002-1202(009) | C8: Fuel - To implement the PEQI quality indicators of Pirivena institutions and Other Programmes | D8: Recurrent | E8: 12000 | F8: =SUMIF(Data_Log!D:D, A8, Data_Log!J:J) -> 0
A9: 6.0 | B9: 126-2-05-002-1402 | C9: Postal and Communication | D9: Recurrent | E9: 1000 | F9: =SUMIF(Data_Log!D:D, A9, Data_Log!J:J) -> 0
A10: 7.0 | B10: 126-2-05-002-1403 | C10: Electricity and Water | D10: Recurrent | E10: 16750 | F10: =SUMIF(Data_Log!D:D, A10, Data_Log!J:J) -> 0
A11: 8.0 | B11: 126-2-05-002-1409(140) | C11: Other- Miscellaneous Service Expenditure | D11: Recurrent | F11: =SUMIF(Data_Log!D:D, A11, Data_Log!J:J) -> 0
A12: 8.1 | B12: 126-2-05-002-1409(140) | C12: District and All-Ceylon Inter-Piriven Language and Literature Competitions | D12: Recurrent | E12: 3000 | F12: =SUMIF(Data_Log!D:D, A12, Data_Log!J:J) -> 0
A13: 8.2 | B13: 126-2-05-002-1409(140) | C13: Printing of Teacher Performance Index and Professional Guidances | D13: Recurrent | E13: 3000 | F13: =SUMIF(Data_Log!D:D, A13, Data_Log!J:J) -> 0
A14: 8.3 | B14: 126-2-05-002-1409(140) | C14: Printing of Class Management Performance Index and Guidances | D14: Recurrent | E14: 3000 | F14: =SUMIF(Data_Log!D:D, A14, Data_Log!J:J) -> 0
A15: 8.4 | B15: 126-2-05-002-1409(140) | C15: Preparation and printing expenses for question papers for end-of-term examinations | D15: Recurrent | E15: 7000 | F15: =SUMIF(Data_Log!D:D, A15, Data_Log!J:J) -> 0
A16: 8.5 | B16: 126-2-05-002-1409(140) | C16: Succession allowances for Pirivena teachers undergoing training at the Seethawaka Teacher Training Institute | D16: Recurrent | E16: 2000 | F16: =SUMIF(Data_Log!D:D, A16, Data_Log!J:J) -> 0
A17: 8.6 | B17: 126-2-05-002-1409(140) | C17: Administrative expenses for holding the Pirivena Education Board | D17: Recurrent | E17: 1500 | F17: =SUMIF(Data_Log!D:D, A17, Data_Log!J:J) -> 0
A18: 8.7 | B18: 126-2-05-002-1409(140) | C18: Providing allowances for extra resource persons assigned to teach Tamil in Pirivenas | D18: Recurrent | E18: 2160 | F18: =SUMIF(Data_Log!D:D, A18, Data_Log!J:J) -> 0
A19: 8.8 | B19: 126-2-05-002-1409(140) | C19: Launching and printing of the "Saragaveshi" Action Research Journal. | D19: Recurrent | E19: 1500 | F19: =SUMIF(Data_Log!D:D, A19, Data_Log!J:J) -> 0
A20: 8.9 | B20: 126-2-05-002-1409(140) | C20: Special extra curricular activities and national talent evaluation program to be held on the occasion of National Pirivena Day | D20: Recurrent | E20: 1500 | F20: =SUMIF(Data_Log!D:D, A20, Data_Log!J:J) -> 0
A21: 8.10 | B21: 126-2-05-002-1409(140) | C21: Participation allowances for monitoring the standards of the Pirivena Education Quality index (PEQI) | D21: Recurrent | E21: 1500 | F21: =SUMIF(Data_Log!D:D, A21, Data_Log!J:J) -> 0
A22: 8.11 | B22: 126-2-05-002-1409(140) | C22: Teacher Training Pay Back (Ed. Dip & Training Programmes) | D22: Recurrent | E22: 1000 | F22: =SUMIF(Data_Log!D:D, A22, Data_Log!J:J) -> 0
A23: 8.12 | B23: 126-2-05-002-1409(140) | C23: Program for evaluating teachers who have demonstrated national talent on the occasion of World Teachers' Day | D23: Recurrent | E23: 2840 | F23: =SUMIF(Data_Log!D:D, A23, Data_Log!J:J) -> 0
A24: 8.13 | B24: 126-2-05-002-1409(140) | C24: Agreemant renewal | D24: Recurrent | E24: 1000
A25: 9.0 | B25: 126-2-05-002-1506 | C25: Property Loan Inters to Public Servants | D25: Recurrent | E25: 6500 | F25: =SUMIF(Data_Log!D:D, A25, Data_Log!J:J) -> 0
A26: 10.0 | B26: 126-2-05-002-1508 | C26: Other -Students Grant for Pirivena | D26: Recurrent | E26: 310000 | F26: =SUMIF(Data_Log!D:D, A26, Data_Log!J:J) -> 0
A27: 11.0 | B27: 126-2-05-010-1501 | C27: "Shoes For Pirivenas Students" Providing shoe gift vouchers to 30,000 Pirivena students. | D27: Recurrent | E27: 90000 | F27: =SUMIF(Data_Log!D:D, A27, Data_Log!J:J) -> 0
A28: 12.0 | B28: 126-1-02-000-2002 | C28: Covering the annual estimated cost for the repair and maintenance of office equipment and electronic devices used in the Pirivena Education Division. | D28: Capital | E28: 8000 | F28: =SUMIF(Data_Log!D:D, A28, Data_Log!J:J) -> 0
A29: 13.0 | B29: 126-1-02-000-2003 | C29: Rehabilitation and Improvement of Capital Assets | D29: Capital | F29: =SUMIF(Data_Log!D:D, A29, Data_Log!J:J) -> 0
A30: 13.1 | B30: 126-1-02-000-2003 | C30: Vehicles | D30: Capital | E30: 10000 | F30: =SUMIF(Data_Log!D:D, A30, Data_Log!J:J) -> 0
A31: 14.0 | B31: 126-1-02-000-2102 | C31: Acquisition of essential office equipment and furniture for the Pirivena Education Division. | D31: Capital | F31: =SUMIF(Data_Log!D:D, A31, Data_Log!J:J) -> 0
A32: 14.1 | B32: 126-1-02-000-2102 | C32: No. of 5 Office Steel Cabinet (Small) | D32: Capital | E32: 262 | F32: =SUMIF(Data_Log!D:D, A32, Data_Log!J:J) -> 0
A33: 14.2 | B33: 126-1-02-000-2102 | C33: Purchase No. of 3 new desktop computers. | D33: Capital | E33: 937 | F33: =SUMIF(Data_Log!D:D, A33, Data_Log!J:J) -> 0
A34: 15.0 | B34: 126-1-02-000-2401 | C34: Staff Officer Training | D34: Capital | F34: =SUMIF(Data_Log!D:D, A34, Data_Log!J:J) -> 0
A35: 15.1 | B35: 126-1-02-000-2401 | C35: Staff Level Officer Training | D35: Capital | E35: 400 | F35: =SUMIF(Data_Log!D:D, A35, Data_Log!J:J) -> 0
A36: 15.2 | B36: 126-1-02-000-2401 | C36: External training programs for tertiary staff belonging to the integrated services | D36: Capital | E36: 400 | F36: =SUMIF(Data_Log!D:D, A36, Data_Log!J:J) -> 0
A37: 15.3 | B37: 126-1-02-000-2401 | C37: Training programs for junior employees | D37: Capital | E37: 200 | F37: =SUMIF(Data_Log!D:D, A37, Data_Log!J:J) -> 0
A38: 16.0 | B38: 126-2-05-002-2205 | C38: Capital Grant to Non-Public Institution | D38: Capital | F38: =SUMIF(Data_Log!D:D, A38, Data_Log!J:J) -> 0
A39: 16.1 | B39: 126-2-05-002-2205 | C39: Renovation of buildings and development of infrastructure facilities in identified Pirivenas | D39: Capital | E39: 88250 | F39: =SUMIF(Data_Log!D:D, A39, Data_Log!J:J) -> 0
A40: 16.2 | B40: 126-2-05-002-2205 | C40: Development of 22 model Pirivenas, one per district out of the 825 currently registered Pirivenas (Rs. 5 million * 22) | D40: Capital | E40: 110000 | F40: =SUMIF(Data_Log!D:D, A40, Data_Log!J:J) -> 0
...

Sheet Users
A1: Username | B1: Password | C1: Role / Designation | D1: Access Level | E1: Allocations | F1: Vote Number | G1: name | H1: title | I1: phone
A2: super_admin | B2: Admin@2026 | C2: Super Admin | D2: All Management | E2: 0 | F2: 0 | G2: කහගල චන්දාලෝක හිමි | H2: සහකාර අධ්‍යක්‍ෂ | I2: 773814242
A3: acc_chief | B3: Chief#Acc26 | C3: Executive | D3: All | E3: Financial Dashboard | F3: 0 | G3: Thanuja Gammuduwathtage | H3: Cheif Accountant | I3: 718026569
A4: addl_sec | B4: SecAddl!26 | C4: Executive | D4: All | E4: Overall AIP Progress | F4: 0 | G4: K.C. Niroshan | H4: Add.Secratery | I4: 071 339 5080
A5: dir_dev | B5: DevDir@2026 | C5: Executive | D5: All | E5: Capital/Recurrent Progress | F5: 0 | G5: කර්නල් අනුර අබේවික්‍රම | H5: අධ්‍යක්ෂ (සංවර්ධන) | I5: 719783574
A6: dir_piriven | B6: PirDir#2026 | C6: Executive | D6: All | E6: Overall Monitoring | F6: 0
A7: It_Media | B7: ItMe@2026 | C7: Executive | D7: All | E7: Overall Monitoring | F7: 0 | G7: කැලේසියඹලාවේ නන්ද හිමි | H7: ස.ස.ගු | I7: 716007003
A8: dep_train | B8: TrainDep!26 | C8: Executive | D8: 16.7, 16.9 | E8: Training Progress | F8: 0
A9: dep_plan | B9: PlanDep#2026 | C9: Executive | D9: 16.1, 16.2, 16.3 | E9: Planning Status | F9: 0
A10: acc_salary | B10: SalAcc#2026 | C10: Subject Officer - Salary and Allowance | D10: 1 | E10: 7600000000 | F10: 1001 / 1003 +2
A11: acc_domestic | B11: DomAcc!2026 | C11: Subject Officer - Domestic | D11: 3 | E11: 20000000 | F11: 1101 +2 | G11: ට‍ෙ | H11: වෙ | I11: 715849449
A12: acc_misc | B12: MiscAcc@2026 | C12: Subject Officer - Other Miscellanies | D12: 8 | E12: 30000000 | F12: 1409 +2
A13: acc_grant | B13: GrantAcc#26 | C13: Subject Officer - Student Grant | D13: 10 | E13: 310000000 | F13: 1508-021 +2
A14: acc_utility | B14: UtilAcc!2026 | C14: Subject Officer - Electricity and Water | D14: 7 | E14: 16750000 | F14: 1403 +2
A15: acc_fuel | B15: FuelAcc@2026 | C15: Subject Officer - Fuel (PEQI) | D15: 5 | E15: 12000000 | F15: 1202 +2
A16: acc_station | B16: StatAcc#2026 | C16: Subject Officer - Stationary Requisites | D16: 4.1, 4.2 | E16: 15000000 | F16: 1201 +2
A17: acc_loan | B17: LoanAcc!2026 | C17: Subject Officer - Property Loan Interest | D17: 9 | E17: 6500000 | F17: 1506 +2
A18: acc_procure | B18: ProcAcc@2026 | C18: Subject Officer - Procurement (Capital) | D18: 16.4, 16.5, 16.6, 16.8, 16.11 | E18: 12575000 | F18: 2205 / 2102 +2
A19: acc_office | B19: OffAcc#2026 | C19: Subject Officer - Office Equipment | D19: 16.10 | E19: 1200000 | F19: 126-1-02-000-2102 +1
A20: admin_off1 | B20: AdmOff1#26 | C20: Subject Officer - Repair & Maintenance - Office Equipment | D20: 12.0 | E20: 8000000 | F20: 126-1-02-000-2002
A21: admin_off2 | B21: AdmOff2!26 | C21: Subject Officer - Rehabilitation & Improvement - Vehicles | D21: 13 | E21: 10000000 | F21: 126-1-02-000-2003
A22: dev_do2 | B22: DevDo1@2026 | C22: Subject Officer - Renovation & Infrastructure in Pirivenas | D22: 16.1, 16.2 | E22: 78250000 | F22: 126-2-05-002-2205
A23: dev_do1 | B23: DevDo2#2026 | C23: Subject Officer - PBPTDP Subject | D23: 5, 16.7.31, 16.2, | E23: 1500000 | F23: 126-2-05-002-2205 | G23: හර්ෂණී වරකාවත්ත | H23: සංවර්ධන නිලධාරී | I23: 769089410 | L23: 16.1, 16.2
A24: dev_do3 | B24: DevDo3!2026 | C24: Subject Officer - Training Institutes Infrastructure (Seethawaka/Veneamulla) | D24: 16.3 | E24: 3000000 | F24: 126-2-05-002-2205 | L24: 16.7.31
A25: sub_sinhala | B25: SinSub#26 | C25: Subject Officer - Sinhala | D25: 16.7.1 | E25: 1800000 | F25: 126-2-05-002-2205 | G25: Vindya Sewwandi | H25: DO | I25: 755768615
A26: sub_pali | B26: PalSub!26 | C26: Subject Officer - Pali | D26: 16.7.2 | E26: 2300000 | F26: 126-2-05-002-2205 | G26: කහගල චන්දාලෝක හිමි | H26: සහකාර අධ්‍යක්‍ෂ | I26: 773814242
A27: sub_sanskrit | B27: SanSub@26 | C27: Subject Officer - Sanskrit | D27: 16.7.3 | E27: 1800000 | F27: 126-2-05-002-2205 | G27: Dilki Madushani | H27: DO | I27: 741693703
A28: sub_tripitaka | B28: TriSub#26 | C28: Subject Officer - Tripitaka Dharma | D28: 16.7.2, 16.7.18, 16.7.21, 16.7.19, 16.7.13, 16.7.4 | E28: 1800000 | F28: 126-2-05-002-2205 | G28: Budugala Jinawansa Tero | H28: DO | I28: 773071950
A29: sub_maths | B29: MatSub!26 | C29: Subject Officer - Mathematics | D29: 16.7.5 | E29: 1800000 | F29: 126-2-05-002-2205
A30: sub_english | B30: EngSub@26 | C30: Subject Officer - English | D30: 16.7.6 | E30: 1800000 | F30: 126-2-05-002-2205 | G30: Sudarshani Wijesekara | H30: MSO | I30: 702606183
A31: sub_tamil | B31: TamSub#26 | C31: Subject Officer - Tamil | D31: 16.7.7 | E31: 1000000 | F31: 126-2-05-002-2205 | G31: පස්සරමුල්ලේ දයාවංස හිමි | H31: සංවර්ධන නිලධාරි | I31: 711965818
A32: sub_socio | B32: SocSub!26 | C32: Subject Officer - Sociology | D32: 16.7.8 | E32: 700000 | F32: 126-2-05-002-2205 | G32: Anusha Jayasundara | H32: DO | I32: 712849564
A33: sub_history | B33: HisSub@26 | C33: Subject Officer - History | D33: 16.7.9 | E33: 1000000 | F33: 126-2-05-002-2205
A34: sub_geo | B34: GeoSub#26 | C34: Subject Officer - Geography | D34: 16.7.10 | E34: 500000 | F34: 126-2-05-002-2205
A35: sub_it | B35: ItSub!26 | C35: Subject Officer - IT | D35: 16.7.11 | E35: 500000 | F35: 126-2-05-002-2205
A36: sub_health | B36: HealSub@26 | C36: Subject Officer - Health Science | D36: 16.7.12 | E36: 500000 | F36: 126-2-05-002-2205
A37: sub_gen_sci | B37: SciSub#26 | C37: Subject Officer - General Science සාමාන්‍ය විද්‍යාව | D37: 16.7.13 | E37: 500000 | F37: 126-2-05-002-2205
A38: sub_drama | B38: DraSub!26 | C38: Subject Officer - Drama and Theater | D38: 16.7.14 | E38: 1000000 | F38: 126-2-05-002-2205
A39: sub_arts | B39: ArtSub@26 | C39: Subject Officer - Arts | D39: 16.7.15 | E39: 500000 | F39: 126-2-05-002-2205
A40: sub_dancing | B40: DanSub#26 | C40: Subject Officer - Dancing | D40: 16.7.16 | E40: 1500000 | F40: 126-2-05-002-2205
...

Sheet Dashboard
B1: අංශය / විෂය (A) | C1: වෙන් කළ මුදල (B) | D1: සත්‍ය වියදම (C) | E1: ඉතිරි මුදල (D) | F1: ප්‍රගතිය % (E)
A2: 16.7.1 | B2: Sinhala | C2: 1800000 | D2: =SUMIF(Data_Log!D:D, A2, Data_Log!J:J) -> 235295 | E2: =C2 - D2 -> 1564705 | F2: =IFERROR(D2/C2, 0) -> 0.13071944
A3: 16.7.2 | B3: Pali | C3: 2300000 | D3: =SUMIF(Data_Log!D:D, A3, Data_Log!J:J) -> 1447412 | E3: =C3 - D3 -> 852588 | F3: =IFERROR(D3/C3, 0) -> 0.62930957
A4: 16.7.3 | B4: Sanskrit | C4: 1800000 | D4: =SUMIF(Data_Log!D:D, A4, Data_Log!J:J) -> 346950 | E4: =C4 - D4 -> 1453050 | F4: =IFERROR(D4/C4, 0) -> 0.19275
A5: 16.7.4 | B5: Tripitaka Dharma | C5: 1800000 | D5: =SUMIF(Data_Log!D:D, A5, Data_Log!J:J) -> 218850 | E5: =C5 - D5 -> 1581150 | F5: =IFERROR(D5/C5, 0) -> 0.12158333
A6: 16.7.5 | B6: Mathematics | C6: 1800000 | D6: =SUMIF(Data_Log!D:D, A6, Data_Log!J:J) -> 0 | E6: =C6 - D6 -> 1800000 | F6: =IFERROR(D6/C6, 0) -> 0
A7: 16.7.6 | B7: English | C7: 1800000 | D7: =SUMIF(Data_Log!D:D, A7, Data_Log!J:J) -> 788164 | E7: =C7 - D7 -> 1011836 | F7: =IFERROR(D7/C7, 0) -> 0.43786889
A8: 16.7.7 | B8: Tamil | C8: 1000000 | D8: =SUMIF(Data_Log!D:D, A8, Data_Log!J:J) -> 0 | E8: =C8 - D8 -> 1000000 | F8: =IFERROR(D8/C8, 0) -> 0
A9: 16.7.8 | B9: Sociology | C9: 700000 | D9: =SUMIF(Data_Log!D:D, A9, Data_Log!J:J) -> 0 | E9: =C9 - D9 -> 700000 | F9: =IFERROR(D9/C9, 0) -> 0
A10: 16.7.9 | B10: History | C10: 1000000 | D10: =SUMIF(Data_Log!D:D, A10, Data_Log!J:J) -> 0 | E10: =C10 - D10 -> 1000000 | F10: =IFERROR(D10/C10, 0) -> 0
A11: 16.7.10 | B11: Geography | C11: 500000 | D11: =SUMIF(Data_Log!D:D, A11, Data_Log!J:J) -> 0 | E11: =C11 - D11 -> 500000 | F11: =IFERROR(D11/C11, 0) -> 0
A12: 16.7.11 | B12: IT | C12: 500000 | D12: =SUMIF(Data_Log!D:D, A12, Data_Log!J:J) -> 0 | E12: =C12 - D12 -> 500000 | F12: =IFERROR(D12/C12, 0) -> 0
A13: 16.7.12 | B13: Health Science | C13: 500000 | D13: =SUMIF(Data_Log!D:D, A13, Data_Log!J:J) -> 0 | E13: =C13 - D13 -> 500000 | F13: =IFERROR(D13/C13, 0) -> 0
... A40: 16.7.31 | B40: Pirivena Base Proffesional Teacher Development Programe (PBPTDP) | C40: 1500000 | D40: =SUMIF(Data_Log!D:D, A40, Data_Log!J:J) -> 69175 | E40: =C40 - D40 -> 1430825 | F40: =IFERROR(D40/C40, 0) -> 0.046116667
E41: =C41 - D41 -> 0
A42: 3 | B42: Domestic | C42: 20000 | D42: =SUMIF(Voucher_Log!D:D, A2, Voucher_Log!H:H) -> 0 | E42: =C42 - D42 -> 20000
A43: 4 | B43: Stationary and office Requisites (Providing stationery to 825 Pirivena institutions) | D43: =SUMIF(Voucher_Log!D:D, A3, Voucher_Log!H:H) -> 0 | E43: =C43 - D43 -> 0
A44: 4.1 | B44: Stationary and office Requisites (Providing stationery to 485 Pirivena institutions) | C44: 7500 | D44: =SUMIF(Voucher_Log!D:D, A4, Voucher_Log!H:H) -> 0 | E44: =C44 - D44 -> 7500
A45: 4.2 | B45: Providing Book sets for llibraries of 825 Pirivenas. | C45: 7500 | D45: =SUMIF(Voucher_Log!D:D, A5, Voucher_Log!H:H) -> 0 | E45: =C45 - D45 -> 7500
A46: 5 | B46: Fuel - To implement the PEQI quality indicators of Pirivena institutions and Other Programmes | C46: 12000 | D46: =SUMIF(Voucher_Log!D:D, A6, Voucher_Log!H:H) -> 0 | E46: =C46 - D46 -> 12000
A47: 6.0 | B47: Postal and Communication | C47: 1000 | D47: =SUMIF(Voucher_Log!D:D, A7, Voucher_Log!H:H) -> 0 | E47: =C47 - D47 -> 1000
A48: 7.0 | B48: Electricity and Water | C48: 16750 | D48: =SUMIF(Voucher_Log!D:D, A8, Voucher_Log!H:H) -> 0 | E48: =C48 - D48 -> 16750
A49: 8.0 | B49: Other- Miscellaneous Service Expenditure | D49: =SUMIF(Voucher_Log!D:D, A9, Voucher_Log!H:H) -> 0 | E49: =C49 - D49 -> 0
A50: 8.1 | B50: District and All-Ceylon Inter-Piriven Language and Literature Competitions | C50: 3000 | D50: =SUMIF(Voucher_Log!D:D, A10, Voucher_Log!H:H) -> 0 | E50: =C50 - D50 -> 3000
A51: 8.2 | B51: Printing of Teacher Performance Index and Professional Guidances | C51: 3000 | D51: =SUMIF(Voucher_Log!D:D, A11, Voucher_Log!H:H) -> 0 | E51: =C51 - D51 -> 3000
A52: 8.3 | B52: Printing of Class Management Performance Index and Guidances | C52: 3000 | D52: =SUMIF(Voucher_Log!D:D, A12, Voucher_Log!H:H) -> 0 | E52: =C52 - D52 -> 3000
A53: 8.4 | B53: Preparation and printing expenses for question papers for end-of-term examinations | C53: 7000 | D53: =SUMIF(Voucher_Log!D:D, A13, Voucher_Log!H:H) -> 0 | E53: =C53 - D53 -> 7000
A54: 8.5 | B54: Succession allowances for Pirivena teachers undergoing training at the Seethawaka Teacher Training Institute | C54: 2000 | D54: =SUMIF(Voucher_Log!D:D, A14, Voucher_Log!H:H) -> 0 | E54: =C54 - D54 -> 2000
A55: 8.6 | B55: Administrative expenses for holding the Pirivena Education Board | C55: 1500 | D55: =SUMIF(Voucher_Log!D:D, A15, Voucher_Log!H:H) -> 0 | E55: =C55 - D55 -> 1500
A56: 8.7 | B56: Providing allowances for extra resource persons assigned to teach Tamil in Pirivenas | C56: 2160 | D56: =SUMIF(Voucher_Log!D:D, A16, Voucher_Log!H:H) -> 0 | E56: =C56 - D56 -> 2160
A57: 8.8 | B57: Launching and printing of the "Saragaveshi" Action Research Journal. | C57: 1500 | D57: =SUMIF(Voucher_Log!D:D, A17, Voucher_Log!H:H) -> 0 | E57: =C57 - D57 -> 1500
A58: 8.9 | B58: Special extra curricular activities and national talent evaluation program to be held on the occasion of National Pirivena Day | C58: 1500 | D58: =SUMIF(Voucher_Log!D:D, A18, Voucher_Log!H:H) -> 0 | E58: =C58 - D58 -> 1500
A59: 8.10 | B59: Participation allowances for monitoring the standards of the Pirivena Education Quality index (PEQI) | C59: 1500 | D59: =SUMIF(Voucher_Log!D:D, A19, Voucher_Log!H:H) -> 0 | E59: =C59 - D59 -> 1500
A60: 8.11 | B60: Teacher Training Pay Back (Ed. Dip & Training Programmes) | C60: 1000 | D60: =SUMIF(Voucher_Log!D:D, A20, Voucher_Log!H:H) -> 0 | E60: =C60 - D60 -> 1000
A61: 8.12 | B61: Program for evaluating teachers who have demonstrated national talent on the occasion of World Teachers' Day | C61: 2840 | D61: =SUMIF(Voucher_Log!D:D, A21, Voucher_Log!H:H) -> 0 | E61: =C61 - D61 -> 2840
... A63: 10.0 | B63: Other -Students Grant for Pirivena | C63: 310000 | D63: =SUMIF(Voucher_Log!D:D, A23, Voucher_Log!H:H) -> 0 | E63: =C63 - D63 -> 310000
A64: 11.0 | B64: "Shoes For Pirivenas Students" Providing shoe gift vouchers to 30,000 Pirivena students. | C64: 90000 | D64: 90000000 | E64: =C64 - D64 -> -89910000
A65: 12.0 | B65: Covering the annual estimated cost for the repair and maintenance of office equipment and electronic devices used in the Pirivena Education Division. | C65: 8000 | D65: =SUMIF(Voucher_Log!D:D, A25, Voucher_Log!H:H) -> 0 | E65: =C65 - D65 -> 8000
A66: 13.0 | B66: Rehabilitation and Improvement of Capital Assets | D66: =SUMIF(Voucher_Log!D:D, A26, Voucher_Log!H:H) -> 0 | E66: =C66 - D66 -> 0
A67: 13.1 | B67: Vehicles | C67: 10000 | D67: =SUMIF(Voucher_Log!D:D, A27, Voucher_Log!H:H) -> 0 | E67: =C67 - D67 -> 10000
...

Sheet Settings
